,0
0,"{""error_code"": ""BAD_REQUEST"", ""message"": ""Encountered an unexpected error while evaluating the model. Verify that the serialized input Dataframe is compatible with the model for inference."", ""stack_trace"": ""Traceback (most recent call last):\n  File \""/home/benjamin/.local/lib/python3.7/site-packages/mlflow/pyfunc/scoring_server/__init__.py\"", line 196, in transformation\n    raw_predictions = model.predict(data)\n  File \""/home/benjamin/.local/lib/python3.7/site-packages/mlflow/pyfunc/model.py\"", line 243, in predict\n    return self.python_model.predict(self.context, model_input)\n  File \""model_selection.py\"", line 31, in predict\n    return self.xgb_model.predict(model_input)\nAttributeError: 'XGBWrapper' object has no attribute 'xgb_model'\n""}"
